<?xml version="1.0"?>
<robot name="AMR_Platform"
  xmlns:xacro="http://www.ros.org/wiki/xacro">

  <material name="amr_body_color">
    <color rgba="0.5 0.4 0.9 1.0"/>
  </material>

  <material name="amr_wheel_color">
    <color rgba="0.1 0.2 0.0 1.0"/>
  </material>
  <!-- BASE LINK -->

  <link name="base_link">
    <static>true</static>
  </link>
  
  <link name="amr_main_body">
    <visual>
      <origin rpy="0 0 0" xyz="0 0 0.01"/>
      <geometry>
        <box size="0.7 0.5 0.14 "/>
      </geometry>
      <material name="amr_body_color"></material>
    </visual>
    <visual>
      <origin rpy="0 0 0" xyz="-0.125 0 0.11"/>
      <geometry>
        <box size="0.45 0.5 0.05 "/>
      </geometry>
      <material name="amr_body_color"></material>
    </visual>
    <visual>
      <origin rpy="0 0 0" xyz="0 0 0.21"/>
      <geometry>
        <box size="0.7 0.5 0.14 "/>
      </geometry>
      <material name="amr_body_color"></material>
    </visual>


    <!--  -->
    <collision>
      <origin rpy="0 0 0" xyz="0 0 0.01"/>
      <geometry>
        <box size="0.7 0.5 0.14 "/>
      </geometry>
    </collision>
    <collision>
      <origin rpy="0 0 0" xyz="-0.125 0 0.11"/>
      <geometry>
        <box size="0.45 0.5 0.05 "/>
      </geometry>
    </collision>
    <collision>
      <origin rpy="0 0 0" xyz="0 0 0.21"/>
      <geometry>
        <box size="0.7 0.5 0.14 "/>
      </geometry>
    </collision>
    <inertial>
      <mass value="10000.07"/>
      <origin rpy="0 0 0" xyz="-0.03 0 0"/>
      <inertia ixx="0.426" ixy="0.0" ixz="0.0" iyy="0.496" iyz="0.0" izz="0.91"/>
    </inertial>
  </link>

  <joint name="main_body_to_base" type="fixed">
    <parent link="base_link"/>
    <child link="amr_main_body"/>
    <origin xyz="0 0 0.09"/>
  </joint>
  <link name="left_wheel">
    <visual>
      <origin rpy="1.5707963267949 0 0" xyz="0 0 0"/>
      <geometry>
        <cylinder length="0.03937" radius="0.088"/>
      </geometry>
      <material name="amr_wheel_color"/>
    </visual>
    <collision>
      <origin rpy="1.5707963267949 0 0" xyz="0 0 0"/>
      <geometry>
        <cylinder length="0.03937" radius="0.088"/>
      </geometry>
    </collision>
    <inertial>
      <mass value="0.17"/>
      <inertia ixx="0.000204" ixy="0.0" ixz="0.0" iyy="0.000306" iyz="0.0" izz="0.000204"/>
    </inertial>
  </link>
  <joint name="left_wheel_joint" type="continuous">
    <axis rpy="0 0 0" xyz="0 1 0"/>
    <parent link="amr_main_body"/>
    <child link="left_wheel"/>
    <origin rpy="0 0 0" xyz="0 0.3 0.000881"/>
  </joint>
  <link name="right_wheel">
    <visual>
      <origin rpy="1.5707963267949 0 0" xyz="0 0 0"/>
      <geometry>
        <cylinder length="0.03937" radius="0.088"/>
      </geometry>
      <material name="amr_wheel_color"/>
    </visual>
    <collision>
      <origin rpy="1.5707963267949 0 0" xyz="0 0 0"/>
      <geometry>
        <cylinder length="0.03937" radius="0.088"/>
      </geometry>
    </collision>
    <inertial>
      <mass value="0.17"/>
      <inertia ixx="0.000204" ixy="0.0" ixz="0.0" iyy="0.000306" iyz="0.0" izz="0.000204"/>
    </inertial>
  </link>
  <joint name="right_wheel_joint" type="continuous">
    <axis rpy="0 0 0" xyz="0 1 0"/>
    <parent link="amr_main_body"/>
    <child link="right_wheel"/>
    <origin rpy="0 0 0" xyz="0 -0.3 0.000881"/>
  </joint>
  <link name="right_front_small_wheel">
    <visual>
      <origin rpy="1.5707963267949 0 0" xyz="0 0 0"/>
      <geometry>
        <cylinder length="0.02775" radius="0.03625"/>
      </geometry>
      <material name="amr_wheel_color"/>
    </visual>
    <collision>
      <origin rpy="1.5707963267949 0 0" xyz="0 0 0"/>
      <geometry>
        <cylinder length="0.02775" radius="0.03625"/>
      </geometry>
    </collision>
    <inertial>
      <mass value="0.17"/>
      <inertia ixx="0.000204" ixy="0.0" ixz="0.0" iyy="0.000306" iyz="0.0" izz="0.000204"/>
    </inertial>
  </link>
  <joint name="right_front_small_wheel_joint" type="continuous">
    <axis rpy="0 0 0" xyz="0 1 0"/>
    <parent link="amr_main_body"/>
    <child link="right_front_small_wheel"/>
    <origin rpy="0 0 0" xyz="0.209 -0.108 -0.049"/>
  </joint>
  <link name="left_front_small_wheel">
    <visual>
      <origin rpy="1.5707963267949 0 0" xyz="0 0 0"/>
      <geometry>
        <cylinder length="0.02775" radius="0.03625"/>
      </geometry>
      <material name="amr_wheel_color"/>
    </visual>
    <collision>
      <origin rpy="1.5707963267949 0 0" xyz="0 0 0"/>
      <geometry>
        <cylinder length="0.02775" radius="0.03625"/>
      </geometry>
    </collision>
    <inertial>
      <mass value="0.17"/>
      <inertia ixx="0.000204" ixy="0.0" ixz="0.0" iyy="0.000306" iyz="0.0" izz="0.000204"/>
    </inertial>
  </link>
  <joint name="left_front_small_wheel_joint" type="continuous">
    <axis rpy="0 0 0" xyz="0 1 0"/>
    <parent link="amr_main_body"/>
    <child link="left_front_small_wheel"/>
    <origin rpy="0 0 0" xyz="0.209 0.108 -0.049"/>
  </joint>
  <link name="left_back_small_wheel">
    <visual>
      <origin rpy="1.5707963267949 0 0" xyz="0 0 0"/>
      <geometry>
        <cylinder length="0.02775" radius="0.03625"/>
      </geometry>
      <material name="amr_wheel_color"/>
    </visual>
    <collision>
      <origin rpy="1.5707963267949 0 0" xyz="0 0 0"/>
      <geometry>
        <cylinder length="0.02775" radius="0.03625"/>
      </geometry>
    </collision>
    <inertial>
      <mass value="0.17"/>
      <inertia ixx="0.000204" ixy="0.0" ixz="0.0" iyy="0.000306" iyz="0.0" izz="0.000204"/>
    </inertial>
  </link>
  <joint name="left_back_small_wheel_joint" type="continuous">
    <axis rpy="0 0 0" xyz="0 1 0"/>
    <parent link="amr_main_body"/>
    <child link="left_back_small_wheel"/>
    <origin rpy="0 0 0" xyz="-0.228 0.156 -0.049"/>
  </joint>
  <link name="right_back_small_wheel">
    <visual>
      <origin rpy="1.5707963267949 0 0" xyz="0 0 0"/>
      <geometry>
        <cylinder length="0.02775" radius="0.03625"/>
      </geometry>
      <material name="amr_wheel_color"/>
    </visual>
    <collision>
      <origin rpy="1.5707963267949 0 0" xyz="0 0 0"/>
      <geometry>
        <cylinder length="0.02775" radius="0.03625"/>
      </geometry>
    </collision>
    <inertial>
      <mass value="0.17"/>
      <inertia ixx="0.000204" ixy="0.0" ixz="0.0" iyy="0.000306" iyz="0.0" izz="0.000204"/>
    </inertial>
  </link>
  <joint name="right_back_small_wheel_joint" type="continuous">
    <axis rpy="0 0 0" xyz="0 1 0"/>
    <parent link="amr_main_body"/>
    <child link="right_back_small_wheel"/>
    <origin rpy="0 0 0" xyz="-0.228 -0.156 -0.049"/>
  </joint>

</robot>